Workbook

Sheet PTJ
A1: BIL. | B1: NAMA PTJ | C1: PTJ | D1: KOD PTJ | E1: PTJ
A2: 1 | B2: PEJ. K.EKSEKUTIF-PKE | C2: PKE | D2: 10110001 | E2: PKE
A3: 2 | B3: PEJ. PUU-PPUU | C3: PPUU | D3: 10110003 | E3: PPUU
A4: 3 | B4: AUDIT & RISIKO-BAR | C4: BAR | D4: 10110004 | E4: BAR
A5: 4 | B5: SUMBER MANUSIA-BSM | C5: BSM | D5: 10120001 | E5: BSM
A6: 5 | B6: TEK. MAKLUMAT-BTM | C6: BTM | D6: 10120002 | E6: BTM
A7: 6 | B7: KEWANGAN & AKAUN-BKA | C7: BKA | D7: 10120003 | E7: BKA
A8: 7 | B8: U.PGRSN FASILITI-UPF | C8: UPF | D8: 10120004 | E8: UPF
A9: 8 | B9: PENGURUSAN LEVI-BPLV | C9: BPLV | D9: 10130001 | E9: BPLV
A10: 9 | B10: PENGUATKUASAAN-BPGK | C10: BPGK | D10: 10130003 | E10: BPGK
A11: 10 | B11: PMTHN KUALITI (BPKB) | C11: BPKB | D11: 10130007 | E11: BPKB
A12: 11 | B12: PBGN TEKNOLOGI (BPT) | C12: BPT | D12: 10140007 | E12: BPT
A13: 12 | B13: PSKTRN BISNES (BPS) | C13: BPS | D13: 10140008 | E13: BPS
... A39: 38 | B39: SD-SANDAKAN | C39: SD | D39: 10200032 | E39: SD

Sheet BAJET 2026
A1: Fund | B1: Funds Center | C1: Funded Program | D1: Consumable Amt | E1: Consumed Amt | F1: Available Amt | G1: Number of DB Records | H1: Status | I1: Funds Center Description | J1: Commitment Item | K1: Commitment Item Description | L1: Funded Program Description | M1: Commitment Item Category
A2: KWI | B2: 10150008 | C2: PI.A0.AA.10150008.01 | D2: 1559400 | E2: 641824.6 | F2: 917575.4 | G2: 2 | I2: PDFTRN KONTRAKTOR&PERSONEL BINAAN-BPKPB | J2: B62000 | K2: BELANJA PROGRAM INDUSTRI | L2: Pendaftaran Kontraktor | M2: 3
A3: KWI | B3: 10170004 | C3: PI.A0.AA.10170004.01 | D3: 1730000 | E3: 342352.43 | F3: 1387647.6 | G3: 2 | I3: PEMBANGUNAN KONTRAKTOR (BPK) | J3: B62000 | K3: BELANJA PROGRAM INDUSTRI | L3: Pendaftaran Kontraktor | M3: 3
A4: KWI | B4: 10200001 | C4: PI.A0.AA.10200001.01 | D4: 2000 | E4: 0 | F4: 2000 | G4: 1 | I4: PL-PERLIS | J4: B62000 | K4: BELANJA PROGRAM INDUSTRI | L4: Pendaftaran Kontraktor | M4: 3
A5: KWI | B5: 10200002 | C5: PI.A0.AA.10200002.01 | D5: 14700 | E5: 0 | F5: 14700 | G5: 1 | I5: KD-KEDAH | J5: B62000 | K5: BELANJA PROGRAM INDUSTRI | L5: Pendaftaran Kontraktor | M5: 3
A6: KWI | B6: 10200003 | C6: PI.A0.AA.10200003.01 | D6: 14700 | E6: 10520.9 | F6: 4179.1 | G6: 2 | I6: PP-PULAU PINANG | J6: B62000 | K6: BELANJA PROGRAM INDUSTRI | L6: Pendaftaran Kontraktor | M6: 3
A7: KWI | B7: 10200004 | C7: PI.A0.AA.10200004.01 | D7: 3900 | E7: 0 | F7: 3900 | G7: 1 | I7: PR-PERAK | J7: B62000 | K7: BELANJA PROGRAM INDUSTRI | L7: Pendaftaran Kontraktor | M7: 3
A8: KWI | B8: 10200005 | C8: PI.A0.AA.10200005.01 | D8: 21600 | E8: 12430 | F8: 9170 | G8: 2 | I8: SL-SELANGOR | J8: B62000 | K8: BELANJA PROGRAM INDUSTRI | L8: Pendaftaran Kontraktor | M8: 3
A9: KWI | B9: 10200006 | C9: PI.A0.AA.10200006.01 | D9: 33800 | E9: 1300 | F9: 32500 | G9: 2 | I9: WP-WILAYAH PERSEKUTUAN (KL) | J9: B62000 | K9: BELANJA PROGRAM INDUSTRI | L9: Pendaftaran Kontraktor | M9: 3
A10: KWI | B10: 10200007 | C10: PI.A0.AA.10200007.01 | D10: 18400 | E10: 10109.91 | F10: 8290.09 | G10: 2 | I10: NS-NEGERI SEMBILAN | J10: B62000 | K10: BELANJA PROGRAM INDUSTRI | L10: Pendaftaran Kontraktor | M10: 3
A11: KWI | B11: 10200008 | C11: PI.A0.AA.10200008.01 | D11: 16200 | E11: 7890 | F11: 8310 | G11: 2 | I11: ML-MELAKA | J11: B62000 | K11: BELANJA PROGRAM INDUSTRI | L11: Pendaftaran Kontraktor | M11: 3
A12: KWI | B12: 10200009 | C12: PI.A0.AA.10200009.01 | D12: 14700 | E12: 10108.8 | F12: 4591.2 | G12: 2 | I12: JH-JOHOR | J12: B62000 | K12: BELANJA PROGRAM INDUSTRI | L12: Pendaftaran Kontraktor | M12: 3
A13: KWI | B13: 10200010 | C13: PI.A0.AA.10200010.01 | D13: 14700 | E13: 10000 | F13: 4700 | G13: 2 | I13: PH-PAHANG | J13: B62000 | K13: BELANJA PROGRAM INDUSTRI | L13: Pendaftaran Kontraktor | M13: 3
... A191: KWI | B191: 10130005 | C191: PI.D0.DG.10130005.01 | D191: 10192000 | E191: 0 | F191: 10192000 | G191: 1 | I191: NA-BAHAGIAN OPERASI SETEMPAT | J191: B62000 | K191: BELANJA PROGRAM INDUSTRI | L191: Perkhidmatan Pelanggan | M191: 3
A192: KWM | B192: 10110001 | D192: 2295000 | E192: 810312.52 | F192: 1484687.5 | G192: 2 | I192: PEJABAT KETUA EKSEKUTIF-PKE | J192: B11000 | K192: EMOLUMEN | M192: 3
A193: KWM | B193: 10110003 | D193: 516000 | E193: 257166.25 | F193: 258833.75 | G193: 2 | I193: PEJABAT PENASIHAT UNDANG-UNDANG-PPUU | J193: B11000 | K193: EMOLUMEN | M193: 3
A194: KWM | B194: 10110004 | D194: 532500 | E194: 228763.27 | F194: 303736.73 | G194: 2 | I194: AUDIT & RISIKO-BAR | J194: B11000 | K194: EMOLUMEN | M194: 3
A195: KWM | B195: 10120001 | D195: 4380000 | E195: 1034666.4 | F195: 3345333.6 | G195: 2 | I195: SUMBER MANUSIA-BSM | J195: B11000 | K195: EMOLUMEN | M195: 3
A196: KWM | B196: 10120002 | D196: 1669000 | E196: 883860.53 | F196: 785139.47 | G196: 2 | I196: TEKNOLOGI MAKLUMAT-BTM | J196: B11000 | K196: EMOLUMEN | M196: 3
A197: KWM | B197: 10120003 | D197: 916000 | E197: 456766.11 | F197: 459233.89 | G197: 2 | I197: KEWANGAN & AKAUN-BKA | J197: B11000 | K197: EMOLUMEN | M197: 3
A198: KWM | B198: 10120004 | D198: 568000 | E198: 297795.1 | F198: 270204.9 | G198: 2 | I198: UNIT PENGURUSAN FASILITI-UPF | J198: B11000 | K198: EMOLUMEN | M198: 3
A199: KWM | B199: 10130001 | D199: 1083000 | E199: 509087.24 | F199: 573912.76 | G199: 2 | I199: PENGURUSAN LEVI-BPLV | J199: B11000 | K199: EMOLUMEN | M199: 3
A200: KWM | B200: 10130003 | D200: 990000 | E200: 497084.25 | F200: 492915.75 | G200: 2 | I200: PENGUATKUASAAN-BPGK | J200: B11000 | K200: EMOLUMEN | M200: 3
A201: KWM | B201: 10130007 | D201: 713000 | E201: 368310.16 | F201: 344689.84 | G201: 2 | I201: PEMATUHAN KUALITI BAHAN (BPKB) | J201: B11000 | K201: EMOLUMEN | M201: 3
A202: KWM | B202: 10140007 | D202: 609000 | E202: 318274.7 | F202: 290725.3 | G202: 2 | I202: PEMBANGUNAN TEKNOLOGI (BPT) | J202: B11000 | K202: EMOLUMEN | M202: 3
A203: KWM | B203: 10140008 | D203: 337000 | E203: 176253.33 | F203: 160746.67 | G203: 2 | I203: PERSEKITARAN BISNES (BPS) | J203: B11000 | K203: EMOLUMEN | M203: 3
... A658: KWP | B658: 10120004 | D658: 70141200 | E658: 0 | F658: 70141200 | G658: 1 | I658: UNIT PENGURUSAN FASILITI-UPF | J658: A93200 | K658: BANGUNAN | M658: 3
A659: KWP | B659: 10120001 | C659: PM.000002.K01 | D659: 0 | E659: 0 | F659: 0 | G659: 1 | I659: SUMBER MANUSIA-BSM | J659: B31000 | K659: BAYARAN PROJEK | L659: P'binaan Kampus ABM Sbh- P'ltkn Kontraktor Binaan | M659: 3
A660: KWP | B660: 10120001 | C660: PM.000002.K02 | D660: 48775200 | E660: 5900610 | F660: 42874590 | G660: 2 | I660: SUMBER MANUSIA-BSM | J660: B31000 | K660: BAYARAN PROJEK | L660: P'binaan Kampus ABM Sbh- Kontraktor KTI Sdn Bhd | M660: 3
A661: KWP | B661: 10120001 | C661: PM.000002.P01 | D661: 500000 | E661: 406404.04 | F661: 93595.96 | G661: 2 | I661: SUMBER MANUSIA-BSM | J661: B31000 | K661: BAYARAN PROJEK | L661: Pembinaan Kampus ABM Sbh-Perunding Arkitek | M661: 3
A662: KWP | B662: 10120001 | C662: PM.000002.P02 | D662: 500000 | E662: 59689.44 | F662: 440310.56 | G662: 2 | I662: SUMBER MANUSIA-BSM | J662: B31000 | K662: BAYARAN PROJEK | L662: P'binaan Kampus ABM Sabah-Perunding Jurutera Sivil | M662: 3
A663: KWP | B663: 10120001 | C663: PM.000002.P03 | D663: 400000 | E663: 139773.6 | F663: 260226.4 | G663: 2 | I663: SUMBER MANUSIA-BSM | J663: B31000 | K663: BAYARAN PROJEK | L663: ABM Sabah-Perunding Jurutera Mekanikal | M663: 3
A664: KWP | B664: 10120001 | C664: PM.000002.P05 | D664: 300000 | E664: 0 | F664: 300000 | G664: 1 | I664: SUMBER MANUSIA-BSM | J664: B31000 | K664: BAYARAN PROJEK | L664: Pembinaan Kampus ABM Sabah-Perunding Ukur Bahan | M664: 3
A665: KWP | B665: 10120001 | C665: PM.000002.P08 | D665: 200000 | E665: 0 | F665: 200000 | G665: 1 | I665: SUMBER MANUSIA-BSM | J665: B31000 | K665: BAYARAN PROJEK | L665: Pembinaan Kampus ABM Sabah-Perunding BIM | M665: 3
A666: KWP | B666: 10120001 | C666: PM.000008.K01 | D666: 6000000 | E666: 2022233.2 | F666: 3977766.8 | G666: 2 | I666: SUMBER MANUSIA-BSM | J666: B31000 | K666: BAYARAN PROJEK | L666: Kompleks CIDB Johor-Perlantikan Kontraktor Binaan | M666: 3
A667: KWP | B667: 10120001 | C667: PM.000008.P01 | D667: 300000 | E667: 0 | F667: 300000 | G667: 1 | I667: SUMBER MANUSIA-BSM | J667: B31000 | K667: BAYARAN PROJEK | L667: Kompleks CIDB Johor-Perunding Arkitek | M667: 3
A668: KWP | B668: 10120001 | C668: PM.000008.P02 | D668: 300000 | E668: 51343.2 | F668: 248656.8 | G668: 2 | I668: SUMBER MANUSIA-BSM | J668: B31000 | K668: BAYARAN PROJEK | L668: Kompleks CIDB Johor-Perunding Jurutera Sivil | M668: 3
A669: KWP | B669: 10120001 | C669: PM.000008.P03 | D669: 200000 | E669: 29376 | F669: 170624 | G669: 2 | I669: SUMBER MANUSIA-BSM | J669: B31000 | K669: BAYARAN PROJEK | L669: Kompleks CIDB Jhr-Perunding Mekanikal & Elektrikal | M669: 3
A670: KWP | B670: 10120001 | C670: PM.000008.P05 | D670: 100000 | E670: 0 | F670: 100000 | G670: 1 | I670: SUMBER MANUSIA-BSM | J670: B31000 | K670: BAYARAN PROJEK | L670: Kompleks CIDB Johor-Perunding Jurukur Bahan | M670: 3
... A680: KWP | B680: 10120004 | C680: PM.000070.K01 | D680: 437100 | E680: 437099 | F680: 1 | G680: 2 | I680: UNIT PENGURUSAN FASILITI-UPF | J680: B31000 | K680: BAYARAN PROJEK | L680: UBAHSUAI PEJABAT CIDB NEGERI PERAK-KONT BINAAN | M680: 3
...

Sheet SUMMARY KOD
A1: BIL. | B1: BIL2. | C1: KATEGORI | D1: ITEM | F1: KOD ITEM | H1: KOD CI | I1: NEW KOD CI | J1: NEW KOD ITEM | K1: NEW KOD ITEM2
A2: A | B2: 1 | C2: HASIL | D2: LEVI KONTRAK | E2: H-A. | F2: LV | H2: LEVI | I2: LEVI | J2: =CONCATENATE(E2,F2) -> H-A.LV
B3: 2 | C3: HASIL | D3: YURAN PENDAFTARAN | E3: H-B. | F3: YP-PK | H3: YP-PK | I3: YP-PK | J3: =CONCATENATE(E3,F3) -> H-B.YP-PK
C4: HASIL | D4: YURAN PENDAFTARAN | E4: H-B. | F4: YP-PB | H4: YP-PPB | I4: YP-PB | J4: =CONCATENATE(E4,F4) -> H-B.YP-PB
B5: 3 | C5: HASIL | D5: FAEDAH & DIVIDEN | E5: H-C. | F5: FD | H5: FDHD | I5: FDHD | J5: =CONCATENATE(E5,F5) -> H-C.FD
B6: 4 | C6: HASIL | D6: PENILAIAN KEMAHIRAN | E6: H-D. | F6: PK | H6: PK | I6: PK | J6: =CONCATENATE(E6,F6) -> H-D.PK
B7: 5 | C7: HASIL | D7: PELBAGAI HASIL | E7: H-E. | F7: 1.LHUP.YK | H7: YK-YKK | I7: -i.YKK | J7: =CONCATENATE(E7,F7) -> H-E.1.LHUP.YK | K7: =CONCATENATE(J7,I7) -> H-E.1.LHUP.YK-i.YKK
C8: HASIL | D8: PELBAGAI HASIL | E8: H-E. | F8: 1.LHUP.YK | H8: YK-YKPB | I8: -ii.YKPB | J8: =CONCATENATE(E8,F8) -> H-E.1.LHUP.YK | K8: =CONCATENATE(J8,I8) -> H-E.1.LHUP.YK-ii.YKPB
C9: HASIL | D9: PELBAGAI HASIL | E9: H-E. | F9: 1.LHUP.YK | H9: YK-YKBS | I9: -iii.YKBS | J9: =CONCATENATE(E9,F9) -> H-E.1.LHUP.YK | K9: =CONCATENATE(J9,I9) -> H-E.1.LHUP.YK-iii.YKBS
C10: HASIL | D10: PELBAGAI HASIL | E10: H-E. | F10: 1.LHUP.YK | H10: YK-YKKorp | I10: -iv.YKKorp | J10: =CONCATENATE(E10,F10) -> H-E.1.LHUP.YK | K10: =CONCATENATE(J10,I10) -> H-E.1.LHUP.YK-iv.YKKorp
C11: HASIL | D11: PELBAGAI HASIL | E11: H-E. | F11: 1.LHUP.YK | H11: YK-YKSHEQ | I11: -v.YKSHEQ | J11: =CONCATENATE(E11,F11) -> H-E.1.LHUP.YK | K11: =CONCATENATE(J11,I11) -> H-E.1.LHUP.YK-v.YKSHEQ
C12: HASIL | D12: PELBAGAI HASIL | E12: H-E. | F12: 1.LHUP.YK | H12: YK-YKBB | I12: -vi.YKBB | J12: =CONCATENATE(E12,F12) -> H-E.1.LHUP.YK | K12: =CONCATENATE(J12,I12) -> H-E.1.LHUP.YK-vi.YKBB
C13: HASIL | D13: PELBAGAI HASIL | E13: H-E. | F13: 1.LHUP.YK | H13: YK-LLYK | I13: -vii.LLYK | J13: =CONCATENATE(E13,F13) -> H-E.1.LHUP.YK | K13: =CONCATENATE(J13,I13) -> H-E.1.LHUP.YK-vii.LLYK
C14: HASIL | D14: PELBAGAI HASIL | E14: H-E. | F14: 1.LHUP.VR | H14: VR-BI | I14: -i.BI | J14: =CONCATENATE(E14,F14) -> H-E.1.LHUP.VR | K14: =CONCATENATE(J14,I14) -> H-E.1.LHUP.VR-i.BI
C15: HASIL | D15: PELBAGAI HASIL | E15: H-E. | F15: 1.LHUP.VR | H15: VR-BT | I15: -ii.BT | J15: =CONCATENATE(E15,F15) -> H-E.1.LHUP.VR | K15: =CONCATENATE(J15,I15) -> H-E.1.LHUP.VR-ii.BT
C16: HASIL | D16: PELBAGAI HASIL | E16: H-E. | F16: 2.LHUP.JUAL DOK. | H16: JUAL-DOK | I16: -i.DOK. | J16: =CONCATENATE(E16,F16) -> H-E.2.LHUP.JUAL DOK. | K16: =CONCATENATE(J16,I16) -> H-E.2.LHUP.JUAL DOK.-i.DOK.
C17: HASIL | D17: PELBAGAI HASIL | E17: H-E. | F17: 2.LHUP.JUAL DOK. | H17: JUAL-TENDER | I17: -ii.TENDER | J17: =CONCATENATE(E17,F17) -> H-E.2.LHUP.JUAL DOK. | K17: =CONCATENATE(J17,I17) -> H-E.2.LHUP.JUAL DOK.-ii.TENDER
C18: HASIL | D18: PELBAGAI HASIL | E18: H-E. | F18: 3.LHUP.SEWA | H18: LLP-SEWA-TNH | I18: -i.TNH | J18: =CONCATENATE(E18,F18) -> H-E.3.LHUP.SEWA | K18: =CONCATENATE(J18,I18) -> H-E.3.LHUP.SEWA-i.TNH
C19: HASIL | D19: PELBAGAI HASIL | E19: H-E. | F19: 3.LHUP.SEWA | H19: LLP-SEWA-BGN | I19: -ii.-BGN | J19: =CONCATENATE(E19,F19) -> H-E.3.LHUP.SEWA | K19: =CONCATENATE(J19,I19) -> H-E.3.LHUP.SEWA-ii.-BGN
C20: HASIL | D20: PELBAGAI HASIL | E20: H-E. | F20: 4.LHUP.CAJ SEKATAN | H20: LLP-UP CAJ SEKATAN | I20: CAJ SEKATAN | J20: =CONCATENATE(E20,F20) -> H-E.4.LHUP.CAJ SEKATAN
C21: HASIL | D21: PELBAGAI HASIL | E21: H-E. | F21: 5.LHUP | H21: LLP-UP | I21: LLHP | J21: =CONCATENATE(E21,F21) -> H-E.5.LHUP
C22: HASIL | D22: PELBAGAI HASIL | E22: H-E. | F22: 6.LHUBP.PENALTI | H22: PENALTI | J22: =CONCATENATE(E22,F22) -> H-E.6.LHUBP.PENALTI
C23: HASIL | D23: PELBAGAI HASIL | E23: H-E. | F23: 7.LHUBP.KOMPAUN | H23: KOMPAUN | J23: =CONCATENATE(E23,F23) -> H-E.7.LHUBP.KOMPAUN
C24: HASIL | D24: PELBAGAI HASIL | E24: H-E. | F24: 8.LHUBP.GERAN | H24: GERAN | J24: =CONCATENATE(E24,F24) -> H-E.8.LHUBP.GERAN
C25: HASIL | D25: PELBAGAI HASIL | E25: H-E. | F25: 9.LHUBP.SUMBGN | H25: SUMBGN | J25: =CONCATENATE(E25,F25) -> H-E.9.LHUBP.SUMBGN
C26: HASIL | D26: PELBAGAI HASIL | E26: H-E. | F26: 10.LLH.JUAL ASET | H26: LLH-JUAL ASET | J26: =CONCATENATE(E26,F26) -> H-E.10.LLH.JUAL ASET
C27: HASIL | D27: PELBAGAI HASIL | E27: H-E. | F27: 11.LLH.HK/PHR LEVI | H27: LLH-PHR LEVI | I27: -i.PHR LEVI | J27: =CONCATENATE(E27,F27) -> H-E.11.LLH.HK/PHR LEVI | K27: =CONCATENATE(J27,I27) -> H-E.11.LLH.HK/PHR LEVI-i.PHR LEVI
C28: HASIL | D28: PELBAGAI HASIL | E28: H-E. | F28: 11.LLH.HK/PHR LEVI | H28: LLH-HK LEVI | I28: -ii.HK LEVI | J28: =CONCATENATE(E28,F28) -> H-E.11.LLH.HK/PHR LEVI | K28: =CONCATENATE(J28,I28) -> H-E.11.LLH.HK/PHR LEVI-ii.HK LEVI
C29: HASIL | D29: PELBAGAI HASIL | E29: H-E. | F29: 12.LLH.MUDHARABAH | H29: LLH-MUDHARABAH | J29: =CONCATENATE(E29,F29) -> H-E.12.LLH.MUDHARABAH
C30: HASIL | D30: PELBAGAI HASIL | E30: H-E. | F30: 13.LLH | H30: LLH | J30: =CONCATENATE(E30,F30) -> H-E.13.LLH
J32: BYR HR
H33: HR | I33: DR BELJ HR | J33: DR BANK | K33: DR PHR
I34: CR PHR LEVI | J34: CR LLH-PHR LEVI | K34: CR AR LEVI
J35: BYR HL
H36: HK HL | I36: DR PHR LEVI | J36: DR BANK
I37: CR AR LEVI | J37: cr LLH-HK LEVI

Sheet HASIL
A1: Fund | B1: Funds Center | C1: Funds Center Description | D1: Commitment Item | E1: KOD AKAUN | F1: KOD CI | G1: Commitment Item Description | H1: PTJ | I1: BAJET 2026 | J1: BAJET 06-2026 | K1: SEBENAR 06-2026 | L1: AUDITED 06-2025 | M1: PRESTASI 06-2026 | N1: PRESTASI 2026 | O1: PRESTASI 26 vs 25 | P1: BAKI BAJET 2026 | R1: BAJET 03-2026 | S1: SEBENAR 03-2026 | T1: AUDITED 03-2025 | U1: PRESTASI 03-2026 | V1: PRESTASI 2026 | W1: PRESTASI 26 vs 25 | X1: BAKI BAJET 2026 | Z1: TEMP | AA1: CI.PTJ
A3: KWM | B3: 10130001 | C3: PENGURUSAN LEVI-BPLV | D3: H62100 | F3: LEVI | G3: LEVI | H3: =VLOOKUP(B3,PTJ!D:E,2,0) -> BPLV | I3: 290000000 | J3: 145000000 | K3: 1.8354243e+08 | L3: 1.56519e+08 | M3: =K3/J3 -> 1.2658099 | N3: =K3/I3 -> 0.63290495 | O3: =K3/L3 -> 1.1726527 | P3: =I3-K3 -> 1.0645757e+08 | R3: 72500000 | S3: 85455559 | T3: 68409608 | U3: =S3/R3 -> 1.1786974 | V3: =S3/I3 -> 0.29467434 | W3: =S3/T3 -> 1.2491748 | X3: =I3-R3 -> 217500000 | Z3: . | AA3: H62100.10130001
A4: KWM | B4: 10150008 | C4: PDFTRN KONTRAKTOR&PERSONEL BINAAN-BPKPB | D4: H71100 | F4: YP-PPB | G4: FI PENDAFTARAN PERSONEL BINAAN | H4: =VLOOKUP(B4,PTJ!D:E,2,0) -> BPKPB | I4: 48625000 | J4: 23000000 | K4: 22854695 | L4: 20636120 | M4: =K4/J4 -> 0.99368239 | N4: =K4/I4 -> 0.47001943 | O4: =K4/L4 -> 1.1075093 | P4: =I4-K4 -> 25770305 | R4: 12156200 | S4: 9882600 | T4: 9687245 | U4: =S4/R4 -> 0.81296787 | V4: =S4/I4 -> 0.20324113 | W4: =S4/T4 -> 1.0201662 | X4: =I4-R4 -> 36468800 | Z4: . | AA4: H71100.10150008
A5: KWM | B5: 10150008 | C5: PDFTRN KONTRAKTOR&PERSONEL BINAAN-BPKPB | D5: H71200 | F5: YP-PK | G5: FI PENDAFTARAN KONTRAKTOR | H5: =VLOOKUP(B5,PTJ!D:E,2,0) -> BPKPB | I5: 48400000 | J5: 25600000 | K5: 25519175 | L5: 23185065 | M5: =K5/J5 -> 0.99684277 | N5: =K5/I5 -> 0.52725568 | O5: =K5/L5 -> 1.100673 | P5: =I5-K5 -> 22880825 | R5: 12100000 | S5: 11619225 | T5: 10882005 | U5: =S5/R5 -> 0.96026653 | V5: =S5/I5 -> 0.24006663 | W5: =S5/T5 -> 1.0677467 | X5: =I5-R5 -> 36300000 | Z5: . | AA5: H71200.10150008
A6: KWM | B6: 10150009 | C6: LATIHAN & AKREDITASI (BLA) | D6: H71300 | F6: PK | G6: PENILAIAN KEMAHIRAN | H6: =VLOOKUP(B6,PTJ!D:E,2,0) -> BLA | I6: 19103600 | J6: 10000000 | K6: 15481700 | L6: 8251490 | M6: =K6/J6 -> 1.54817 | N6: =K6/I6 -> 0.81040746 | O6: =K6/L6 -> 1.8762308 | P6: =I6-K6 -> 3621900 | R6: 4775900 | S6: 7515230 | T6: 3565360 | U6: =S6/R6 -> 1.5735736 | V6: =S6/I6 -> 0.39339339 | W6: =S6/T6 -> 2.1078461 | X6: =I6-R6 -> 14327700 | Z6: . | AA6: H71300.10150009
A7: KWM | B7: 10120003 | C7: KEWANGAN & AKAUN-BKA | D7: H75100 | F7: FDHD | G7: FAEDAH DAN PEROLEHAN DARI PELABURAN | H7: =VLOOKUP(B7,PTJ!D:E,2,0) -> BKA | I7: 24782600 | J7: 12392600 | K7: 13213931 | L7: 12255022 | M7: =K7/J7 -> 1.0662759 | N7: =K7/I7 -> 0.5331939 | O7: =K7/L7 -> 1.0782462 | P7: =I7-K7 -> 11568669 | R7: 6195600 | S7: 6474873.2 | T7: 5947757.1 | U7: =S7/R7 -> 1.045076 | V7: =S7/I7 -> 0.2612669 | W7: =S7/T7 -> 1.0886243 | X7: =I7-R7 -> 18587000 | Z7: . | AA7: H75100.10120003
A8: KWM | B8: 10200001 | C8: PL-PERLIS | D8: H75100 | F8: FDHD | G8: FAEDAH DAN PEROLEHAN DARI PELABURAN | H8: =VLOOKUP(B8,PTJ!D:E,2,0) -> PL | I8: 100 | J8: 100 | K8: 28.57 | L8: 28.29 | M8: =K8/J8 -> 0.2857 | N8: =K8/I8 -> 0.2857 | O8: =K8/L8 -> 1.0098975 | P8: =I8-K8 -> 71.43 | R8: 100 | S8: 11.96 | T8: 15.47 | U8: =S8/R8 -> 0.1196 | V8: =S8/I8 -> 0.1196 | W8: =S8/T8 -> 0.77310924 | X8: =I8-R8 -> 0 | Z8: . | AA8: H75100.10200001
A9: KWM | B9: 10200002 | C9: KD-KEDAH | D9: H75100 | F9: FDHD | G9: FAEDAH DAN PEROLEHAN DARI PELABURAN | H9: =VLOOKUP(B9,PTJ!D:E,2,0) -> KD | I9: 3200 | J9: 1000 | K9: 948.49 | L9: 1653.14 | M9: =K9/J9 -> 0.94849 | N9: =K9/I9 -> 0.29640312 | O9: =K9/L9 -> 0.57375056 | P9: =I9-K9 -> 2251.51 | R9: 800 | S9: 152.64 | T9: 774.91 | U9: =S9/R9 -> 0.1908 | V9: =S9/I9 -> 0.0477 | W9: =S9/T9 -> 0.19697771 | X9: =I9-R9 -> 2400 | Z9: . | AA9: H75100.10200002
A10: KWM | B10: 10200003 | C10: PP-PULAU PINANG | D10: H75100 | F10: FDHD | G10: FAEDAH DAN PEROLEHAN DARI PELABURAN | H10: =VLOOKUP(B10,PTJ!D:E,2,0) -> PP | I10: 600 | J10: 300 | K10: 213.49 | L10: 290.11 | M10: =K10/J10 -> 0.71163333 | N10: =K10/I10 -> 0.35581667 | O10: =K10/L10 -> 0.73589328 | P10: =I10-K10 -> 386.51 | R10: 200 | S10: 191.77 | T10: 178.44 | U10: =S10/R10 -> 0.95885 | V10: =S10/I10 -> 0.31961667 | W10: =S10/T10 -> 1.074703 | X10: =I10-R10 -> 400 | Z10: . | AA10: H75100.10200003
A11: KWM | B11: 10200005 | C11: SL-SELANGOR | D11: H75100 | F11: FDHD | G11: FAEDAH DAN PEROLEHAN DARI PELABURAN | H11: =VLOOKUP(B11,PTJ!D:E,2,0) -> SL | I11: 1600 | J11: 500 | K11: 439.78 | L11: 1198.2 | M11: =K11/J11 -> 0.87956 | N11: =K11/I11 -> 0.2748625 | O11: =K11/L11 -> 0.36703388 | P11: =I11-K11 -> 1160.22 | R11: 400 | S11: 187.77 | T11: 717.32 | U11: =S11/R11 -> 0.469425 | V11: =S11/I11 -> 0.11735625 | W11: =S11/T11 -> 0.26176602 | X11: =I11-R11 -> 1200 | Z11: . | AA11: H75100.10200005
A12: KWM | B12: 10200006 | C12: WP-WILAYAH PERSEKUTUAN (KL) | D12: H75100 | F12: FDHD | G12: FAEDAH DAN PEROLEHAN DARI PELABURAN | H12: =VLOOKUP(B12,PTJ!D:E,2,0) -> WP | I12: 1500 | J12: 600 | K12: 521.42 | L12: 882.19 | M12: =K12/J12 -> 0.86903333 | N12: =K12/I12 -> 0.34761333 | O12: =K12/L12 -> 0.59105181 | P12: =I12-K12 -> 978.58 | R12: 300 | S12: 263.44 | T12: 349.71 | U12: =S12/R12 -> 0.87813333 | V12: =S12/I12 -> 0.17562667 | W12: =S12/T12 -> 0.75330989 | X12: =I12-R12 -> 1200 | Z12: . | AA12: H75100.10200006
A13: KWM | B13: 10200007 | C13: NS-NEGERI SEMBILAN | D13: H75100 | F13: FDHD | G13: FAEDAH DAN PEROLEHAN DARI PELABURAN | H13: =VLOOKUP(B13,PTJ!D:E,2,0) -> NS | I13: 200 | J13: 100 | K13: 13.76 | L13: 54.89 | M13: =K13/J13 -> 0.1376 | N13: =K13/I13 -> 0.0688 | O13: =K13/L13 -> 0.25068318 | P13: =I13-K13 -> 186.24 | R13: 100 | S13: 11.5 | T13: 35.77 | U13: =S13/R13 -> 0.115 | V13: =S13/I13 -> 0.0575 | W13: =S13/T13 -> 0.32149846 | X13: =I13-R13 -> 100 | Z13: . | AA13: H75100.10200007
A14: KWM | B14: 10200008 | C14: ML-MELAKA | D14: H75100 | F14: FDHD | G14: FAEDAH DAN PEROLEHAN DARI PELABURAN | H14: =VLOOKUP(B14,PTJ!D:E,2,0) -> ML | I14: 600 | J14: 200 | K14: 156.81 | L14: 367.29 | M14: =K14/J14 -> 0.78405 | N14: =K14/I14 -> 0.26135 | O14: =K14/L14 -> 0.42693784 | P14: =I14-K14 -> 443.19 | R14: 200 | S14: 156.81 | T14: 225.18 | U14: =S14/R14 -> 0.78405 | V14: =S14/I14 -> 0.26135 | W14: =S14/T14 -> 0.69637623 | X14: =I14-R14 -> 400 | Z14: . | AA14: H75100.10200008
... A23: KWM | B23: 10200032 | C23: SD-SANDAKAN | D23: H75100 | F23: FDHD | G23: FAEDAH DAN PEROLEHAN DARI PELABURAN | H23: =VLOOKUP(B23,PTJ!D:E,2,0) -> SD | I23: 100 | J23: 100 | K23: 34.26 | L23: 29.2 | M23: =K23/J23 -> 0.3426 | N23: =K23/I23 -> 0.3426 | O23: =K23/L23 -> 1.1732877 | P23: =I23-K23 -> 65.74 | R23: 100 | S23: 15.77 | T23: 14.31 | U23: =S23/R23 -> 0.1577 | V23: =S23/I23 -> 0.1577 | W23: =S23/T23 -> 1.1020266 | X23: =I23-R23 -> 0 | Z23: . | AA23: H75100.10200032
A24: KWM | B24: 10150008 | C24: PDFTRN KONTRAKTOR&PERSONEL BINAAN-BPKPB | D24: H72100 | E24: H72101 | F24: YK-YKK | G24: YURAN KURSUS | H24: =VLOOKUP(B24,PTJ!D:E,2,0) -> BPKPB | I24: 385000 | J24: 75000 | K24: 63800 | L24: 110550 | M24: =K24/J24 -> 0.85066667 | N24: =K24/I24 -> 0.16571429 | O24: =K24/L24 -> 0.57711443 | P24: =I24-K24 -> 321200 | R24: 96200 | S24: 3000 | T24: 33850 | U24: =S24/R24 -> 0.031185031 | V24: =S24/I24 -> 0.0077922078 | W24: =S24/T24 -> 0.088626292 | X24: =I24-R24 -> 288800 | Z24: . | AA24: H72100.10150008
A25: KWM | B25: 10150009 | C25: LATIHAN & AKREDITASI (BLA) | D25: H72100 | E25: H72101 | F25: YK-YKK | G25: YURAN KURSUS | H25: =VLOOKUP(B25,PTJ!D:E,2,0) -> BLA | I25: 9576000 | J25: 7425000 | K25: 5685525 | L25: 4545300 | M25: =K25/J25 -> 0.76572727 | N25: =K25/I25 -> 0.5937265 | O25: =K25/L25 -> 1.250858 | P25: =I25-K25 -> 3890475 | R25: 2394000 | S25: 2440400 | T25: 2273100 | U25: =S25/R25 -> 1.0193818 | V25: =S25/I25 -> 0.25484545 | W25: =S25/T25 -> 1.0735999 | X25: =I25-R25 -> 7182000 | Z25: . | AA25: H72100.10150009
A26: KWM | B26: 10150009 | C26: LATIHAN & AKREDITASI (BLA) | D26: H72100 | E26: H72102 | F26: YK-YKPB | G26: YURAN KURSUS | H26: =VLOOKUP(B26,PTJ!D:E,2,0) -> BLA | I26: 2079000 | J26: 519700 | K26: 417450 | L26: 1001255 | M26: =K26/J26 -> 0.80325188 | N26: =K26/I26 -> 0.20079365 | O26: =K26/L26 -> 0.41692676 | P26: =I26-K26 -> 1661550 | R26: 519700 | S26: 209225 | T26: 610305 | U26: =S26/R26 -> 0.40258803 | V26: =S26/I26 -> 0.10063733 | W26: =S26/T26 -> 0.34282039 | X26: =I26-R26 -> 1559300 | Z26: . | AA26: H72100.10150009
A27: KWM | B27: 10140008 | C27: PERSEKITARAN BISNES (BPS) | D27: H72100 | E27: H72103 | F27: YK-YKBS | G27: YURAN KURSUS | H27: =VLOOKUP(B27,PTJ!D:E,2,0) -> BPS | I27: 40000 | J27: 0 | K27: 0 | L27: 0 | M27: =K27/J27 -> #DIV/0! | N27: =K27/I27 -> 0 | O27: =K27/L27 -> #DIV/0! | P27: =I27-K27 -> 40000 | R27: 0 | S27: 0 | T27: 0 | U27: =S27/R27 -> #DIV/0! | V27: =S27/I27 -> 0 | W27: =S27/T27 -> #DIV/0! | X27: =I27-R27 -> 40000 | Z27: . | AA27: H72100.10140008
A28: KWM | B28: 10160003 | C28: KOMUNIKASI KORPORAT-BKK | D28: H72100 | E28: H72105 | F28: YK-YKKorp | G28: YURAN KURSUS | H28: =VLOOKUP(B28,PTJ!D:E,2,0) -> BKK | I28: 100000 | J28: 0 | K28: 0 | L28: 0 | M28: =K28/J28 -> #DIV/0! | N28: =K28/I28 -> 0 | O28: =K28/L28 -> #DIV/0! | P28: =I28-K28 -> 100000 | R28: 0 | S28: 0 | T28: 0 | U28: =S28/R28 -> #DIV/0! | V28: =S28/I28 -> 0 | W28: =S28/T28 -> #DIV/0! | X28: =I28-R28 -> 100000 | Z28: . | AA28: H72100.10160003
A29: KWM | B29: 10140007 | C29: PEMBANGUNAN TEKNOLOGI (BPT) | D29: H72100 | E29: H72106 | F29: YK-YKT | G29: YURAN KURSUS | H29: BPT | I29: 0 | J29: 0 | K29: 5695 | L29: 0 | M29: =K29/J29 -> #DIV/0! | N29: =K29/I29 -> #DIV/0! | O29: =K29/L29 -> #DIV/0! | P29: =I29-K29 -> -5695
A30: KWM | B30: 10140007 | C30: PEMBANGUNAN TEKNOLOGI (BPT) | D30: H72100 | E30: H72107 | F30: YK-YKSHEQ | G30: YURAN KURSUS | H30: BPT | I30: 0 | J30: 0 | K30: 21700 | L30: 7900 | M30: =K30/J30 -> #DIV/0! | N30: =K30/I30 -> #DIV/0! | O30: =K30/L30 -> 2.7468354 | P30: =I30-K30 -> -21700 | S30: 5000 | T30: 0 | U30: =S30/#REF! -> #REF! | V30: =S30/#REF! -> #REF! | W30: =S30/T30 -> #DIV/0! | X30: =#REF!-#REF! -> #REF!
A31: KWM | B31: 10130007 | C31: PEMATUHAN KUALITI BAHAN (BPKB) | D31: H72100 | E31: H72108 | F31: YK-YKBB | G31: YURAN KURSUS | H31: BPKB | I31: 0 | J31: 0 | K31: 5450 | L31: 550 | M31: =K31/J31 -> #DIV/0! | N31: =K31/I31 -> #DIV/0! | O31: =K31/L31 -> 9.9090909 | P31: =I31-K31 -> -5450 | S31: 1500 | T31: 0 | U31: =S31/#REF! -> #REF! | V31: =S31/#REF! -> #REF! | W31: =S31/T31 -> #DIV/0! | X31: =#REF!-#REF! -> #REF!
A32: KWM | B32: 10110003 | C32: PEJABAT PENASIHAT UNDANG-UNDANG-PPUU | D32: H72100 | E32: H72199 | F32: YK-LLYK | G32: YURAN KURSUS | H32: =VLOOKUP(B32,PTJ!D:E,2,0) -> PPUU | I32: 5000 | J32: 0 | K32: 0 | L32: 0 | M32: =K32/J32 -> #DIV/0! | N32: =K32/I32 -> 0 | O32: =K32/L32 -> #DIV/0! | P32: =I32-K32 -> 5000 | R32: 0 | S32: 0 | T32: 0 | U32: =S32/R32 -> #DIV/0! | V32: =S32/I32 -> 0 | W32: =S32/T32 -> #DIV/0! | X32: =I32-R32 -> 5000 | Z32: . | AA32: H72100.10110003
A33: KWM | B33: 10170003 | C33: PEMBANGUNAN PERSONEL BINAAN (BPB) | D33: H72100 | E33: H72199 | F33: YK-LLYK | G33: YURAN KURSUS | H33: =VLOOKUP(B33,PTJ!D:E,2,0) -> BPB | I33: 70000 | J33: 0 | K33: 0 | L33: 0 | M33: =K33/J33 -> #DIV/0! | N33: =K33/I33 -> 0 | O33: =K33/L33 -> #DIV/0! | P33: =I33-K33 -> 70000 | R33: 0 | S33: 0 | T33: 0 | U33: =S33/R33 -> #DIV/0! | V33: =S33/I33 -> 0 | W33: =S33/T33 -> #DIV/0! | X33: =I33-R33 -> 70000 | Z33: . | AA33: H72100.10170003
A34: KWM | B34: 10170004 | C34: PEMBANGUNAN KONTRAKTOR (BPK) | D34: H72100 | E34: H72199 | F34: YK-LLYK | G34: YURAN KURSUS | H34: =VLOOKUP(B34,PTJ!D:E,2,0) -> BPK | I34: 730500 | J34: 0 | K34: 0 | L34: 0 | M34: =K34/J34 -> #DIV/0! | N34: =K34/I34 -> 0 | O34: =K34/L34 -> #DIV/0! | P34: =I34-K34 -> 730500 | R34: 0 | S34: 0 | T34: 0 | U34: =S34/R34 -> #DIV/0! | V34: =S34/I34 -> 0 | W34: =S34/T34 -> #DIV/0! | X34: =I34-R34 -> 730500 | Z34: . | AA34: H72100.10170004
A35: KWM | B35: 10120003 | C35: KEWANGAN & AKAUN-BKA | D35: H72100 | E35: H72199 | F35: YK-LLYK | G35: YURAN KURSUS | H35: BKA | I35: 0 | J35: 0 | K35: 2400 | L35: 0 | M35: =K35/J35 -> #DIV/0! | N35: =K35/I35 -> #DIV/0! | O35: =K35/L35 -> #DIV/0! | P35: =I35-K35 -> -2400 | S35: 0 | T35: 0 | U35: =S35/R35 -> #DIV/0! | V35: =S35/I35 -> #DIV/0! | W35: =S35/T35 -> #DIV/0! | X35: =I35-R35 -> 0
A36: KWM | B36: 10200030 | C36: SB-SABAH | D36: H72100 | E36: H72199 | F36: YK-LLYK | G36: YURAN KURSUS | H36: SB | I36: 0 | J36: 0 | K36: 0 | L36: 9900 | M36: =K36/J36 -> #DIV/0! | N36: =K36/I36 -> #DIV/0! | O36: =K36/L36 -> 0 | P36: =I36-K36 -> 0 | S36: 0 | T36: 0 | U36: =S36/R36 -> #DIV/0! | V36: =S36/I36 -> #DIV/0! | W36: =S36/T36 -> #DIV/0! | X36: =I36-R36 -> 0
A37: KWM | B37: 10130007 | C37: PEMATUHAN KUALITI BAHAN (BPKB) | D37: H72200 | E37: H72201 | F37: VR-BI | G37: BAYARAN VERIFIKASI | H37: =VLOOKUP(B37,PTJ!D:E,2,0) -> BPKB | I37: 12650000 | J37: 9000000 | K37: 7127700 | L37: 6442300 | M37: =K37/J37 -> 0.79196667 | N37: =K37/I37 -> 0.56345455 | O37: =K37/L37 -> 1.1063906 | P37: =I37-K37 -> 5522300 | R37: 3162500 | S37: 3372300 | T37: 2868900 | U37: =S37/R37 -> 1.0663399 | V37: =S37/I37 -> 0.26658498 | W37: =S37/T37 -> 1.1754679 | X37: =I37-R37 -> 9487500 | Z37: . | AA37: H72200.10130007
A38: KWM | B38: 10130007 | C38: PEMATUHAN KUALITI BAHAN (BPKB) | D38: H72200 | E38: H72202 | F38: VR-BT | G38: BAYARAN VERIFIKASI | H38: =VLOOKUP(B38,PTJ!D:E,2,0) -> BPKB | I38: 1537500 | J38: 1000000 | K38: 816750 | L38: 769500 | M38: =K38/J38 -> 0.81675 | N38: =K38/I38 -> 0.53121951 | O38: =K38/L38 -> 1.0614035 | P38: =I38-K38 -> 720750 | R38: 384400 | S38: 392250 | T38: 411750 | U38: =S38/R38 -> 1.0204214 | V38: =S38/I38 -> 0.25512195 | W38: =S38/T38 -> 0.95264117 | X38: =I38-R38 -> 1153100 | Z38: . | AA38: H72200.10130007
A39: KWM | B39: 10140008 | C39: PERSEKITARAN BISNES (BPS) | D39: H73100 | E39: H73101 | F39: JUAL-DOK | G39: JUALAN BARANG-BARANG CETAK | H39: =VLOOKUP(B39,PTJ!D:E,2,0) -> BPS | I39: 22900 | J39: 6000 | K39: 0 | L39: 3045 | M39: =K39/J39 -> 0 | N39: =K39/I39 -> 0 | O39: =K39/L39 -> 0 | P39: =I39-K39 -> 22900 | R39: 0 | S39: 0 | T39: 2250 | U39: =S39/R39 -> #DIV/0! | V39: =S39/I39 -> 0 | W39: =S39/T39 -> 0 | X39: =I39-R39 -> 22900 | Z39: . | AA39: H73100.10140008
A40: KWM | B40: 10140007 | D40: H73100 | E40: H73101 | F40: JUAL-DOK | G40: JUALAN BARANG-BARANG CETAK | H40: BPT | I40: 0 | J40: 0 | K40: 3045 | L40: 2325 | M40: =K40/J40 -> #DIV/0! | N40: =K40/I40 -> #DIV/0! | O40: =K40/L40 -> 1.3096774 | P40: =I40-K40 -> -3045 | R40: 0 | S40: 1470 | T40: 1065 | U40: =S40/R40 -> #DIV/0! | V40: =S40/I40 -> #DIV/0! | W40: =S40/T40 -> 1.3802817 | X40: =I40-R40 -> 0 | Z40: . | AA40: H73100.10140007
A41: KWM | B41: 10160003 | D41: H73100 | E41: H73101 | F41: JUAL-DOK | G41: JUALAN BARANG-BARANG CETAK | H41: BKK | I41: 0 | J41: 0 | K41: 300 | L41: 0 | M41: =K41/J41 -> #DIV/0! | N41: =K41/I41 -> #DIV/0! | O41: =K41/L41 -> #DIV/0! | P41: =I41-K41 -> -300 | R41: 0 | S41: 300 | T41: 0 | U41: =S41/R41 -> #DIV/0! | V41: =S41/I41 -> #DIV/0! | W41: =S41/T41 -> #DIV/0! | X41: =I41-R41 -> 0 | Z41: . | AA41: H73100.10160003
A42: KWM | B42: 10200003 | D42: H73100 | E42: H73101 | F42: JUAL-DOK | G42: JUALAN BARANG-BARANG CETAK | H42: PP | I42: 0 | J42: 0 | K42: 0 | L42: 150 | M42: =K42/J42 -> #DIV/0! | N42: =K42/I42 -> #DIV/0! | O42: =K42/L42 -> 0 | P42: =I42-K42 -> 0 | R42: 0 | S42: 0 | T42: 150 | U42: =S42/R42 -> #DIV/0! | V42: =S42/I42 -> #DIV/0! | W42: =S42/T42 -> 0 | X42: =I42-R42 -> 0 | Z42: . | AA42: H73100.10200003
A43: KWM | B43: 10200004 | D43: H73100 | E43: H73101 | F43: JUAL-DOK | G43: JUALAN BARANG-BARANG CETAK | H43: PR | I43: 0 | J43: 0 | K43: 1200 | L43: 300 | M43: =K43/J43 -> #DIV/0! | N43: =K43/I43 -> #DIV/0! | O43: =K43/L43 -> 4 | P43: =I43-K43 -> -1200 | R43: 0 | S43: 150 | T43: 0 | U43: =S43/R43 -> #DIV/0! | V43: =S43/I43 -> #DIV/0! | W43: =S43/T43 -> #DIV/0! | X43: =I43-R43 -> 0 | Z43: . | AA43: H73100.10200004
A44: KWM | B44: 10200012 | D44: H73100 | E44: H73101 | F44: JUAL-DOK | G44: JUALAN BARANG-BARANG CETAK | H44: KN | I44: 0 | J44: 0 | K44: 300 | L44: 0 | M44: =K44/J44 -> #DIV/0! | N44: =K44/I44 -> #DIV/0! | O44: =K44/L44 -> #DIV/0! | P44: =I44-K44 -> -300 | R44: 0 | S44: 150 | T44: 0 | U44: =S44/R44 -> #DIV/0! | V44: =S44/I44 -> #DIV/0! | W44: =S44/T44 -> #DIV/0! | X44: =I44-R44 -> 0 | Z44: . | AA44: H73100.10200012
A45: KWM | B45: 10200009 | C45: JH-JOHOR | D45: H73100 | E45: H73101 | F45: JUAL-DOK | G45: JUALAN BARANG-BARANG CETAK | H45: JH | J45: 0 | K45: 0 | L45: 300 | M45: =K45/J45 -> #DIV/0! | N45: =K45/I45 -> #DIV/0! | O45: =K45/L45 -> 0 | P45: =I45-K45 -> 0
A46: KWM | B46: 10120001 | C46: SUMBER MANUSIA-BSM | D46: H73100 | E46: H73102 | F46: JUAL-TENDER | G46: JUALAN BARANG-BARANG CETAK | H46: =VLOOKUP(B46,PTJ!D:E,2,0) -> BSM | I46: 80000 | J46: 14000 | K46: 10750 | L46: 7600 | M46: =K46/J46 -> 0.76785714 | N46: =K46/I46 -> 0.134375 | O46: =K46/L46 -> 1.4144737 | P46: =I46-K46 -> 69250 | R46: 20000 | S46: 6400 | T46: 2100 | U46: =S46/R46 -> 0.32 | V46: =S46/I46 -> 0.08 | W46: =S46/T46 -> 3.047619 | X46: =I46-R46 -> 60000 | Z46: . | AA46: H73100.10120001
A47: KWM | B47: 10200008 | D47: H73100 | E47: H73102 | F47: JUAL-TENDER | G47: JUALAN BARANG-BARANG CETAK | H47: ML | I47: 0 | J47: 0 | K47: 350 | L47: 50 | M47: =K47/J47 -> #DIV/0! | N47: =K47/I47 -> #DIV/0! | O47: =K47/L47 -> 7 | P47: =I47-K47 -> -350 | R47: 0 | S47: 350 | T47: 50 | U47: =S47/R47 -> #DIV/0! | V47: =S47/I47 -> #DIV/0! | W47: =S47/T47 -> 7 | X47: =I47-R47 -> 0 | Z47: . | AA47: H73100.10200008
A48: KWM | B48: 10200030 | D48: H73100 | E48: H73102 | F48: JUAL-TENDER | G48: JUALAN BARANG-BARANG CETAK | H48: SB | I48: 0 | J48: 0 | K48: 200 | L48: 70000 | M48: =K48/J48 -> #DIV/0! | N48: =K48/I48 -> #DIV/0! | O48: =K48/L48 -> 0.0028571429 | P48: =I48-K48 -> -200 | R48: 0 | S48: 200 | U48: =S48/R48 -> #DIV/0! | V48: =S48/I48 -> #DIV/0! | W48: =S48/T48 -> #DIV/0! | X48: =I48-R48 -> 0 | Z48: . | AA48: H73100.10200030
A49: KWM | B49: 10150008 | C49: PDFTRN KONTRAKTOR&PERSONEL BINAAN-BPKPB | D49: H76100 | E49: H76102 | F49: PENALTI | G49: PENALTI & DENDA | H49: =VLOOKUP(B49,PTJ!D:E,2,0) -> BPKPB | I49: 650000 | J49: 284500 | K49: 240200 | L49: 366200 | M49: =K49/J49 -> 0.84428822 | N49: =K49/I49 -> 0.36953846 | O49: =K49/L49 -> 0.65592572 | P49: =I49-K49 -> 409800 | R49: 162500 | S49: 105200 | T49: 204000 | U49: =S49/R49 -> 0.64738462 | V49: =S49/I49 -> 0.16184615 | W49: =S49/T49 -> 0.51568627 | X49: =I49-R49 -> 487500 | Z49: . | AA49: H76100.10150008
...

Sheet B.MGRS
A1: Fund | B1: Funds Center | C1: Funds Center Description | D1: Commitment Item | E1: KOD CI | F1: Commitment Item Description | G1: PTJ | H1: BAJET 2026 | I1: BAJET 06-2026 | J1: SEBENAR 06-2026 | K1: AUDITED 06-2025 | L1: PRESTASI 06-2026 | M1: PRESTASI 2026 | N1: PRESTASI 26 vs 25 | O1: BAKI BAJET 2026 | Q1: BAJET 03-2026 | R1: SEBENAR 03-2026 | S1: AUDITED 03-2025 | T1: PRESTASI 03-2026 | U1: PRESTASI 2026 | V1: PRESTASI 26 vs 25 | W1: BAKI BAJET 2026
A2: KWM | B2: 10110001 | C2: PEJABAT KETUA EKSEKUTIF-PKE | D2: B11000 | E2: 1-EMO | F2: EMOLUMEN | G2: PKE | H2: 2295000 | I2: 700000 | J2: 672727.52 | K2: 869367.51 | L2: =J2/I2 -> 0.96103931 | M2: =J2/H2 -> 0.29312746 | N2: =J2/K2 -> 0.77381258 | O2: =H2-J2 -> 1622272.5 | Q2: 390000 | R2: 363674.67 | S2: 451719.1 | T2: =R2/Q2 -> 0.93249915 | U2: =R2/H2 -> 0.15846391 | V2: =R2/S2 -> 0.80509031 | W2: =H2-Q2 -> 1905000 | AB2: 10110001 | AC2: 2295000
A3: KWM | B3: 10110003 | C3: PEJABAT PENASIHAT UNDANG-UNDANG-PPUU | D3: B11000 | E3: 1-EMO | F3: EMOLUMEN | G3: PPUU | H3: 516000 | I3: 250000 | J3: 220201.69 | K3: 204052.44 | L3: =J3/I3 -> 0.88080676 | M3: =J3/H3 -> 0.42674746 | N3: =J3/K3 -> 1.0791426 | O3: =H3-J3 -> 295798.31 | Q3: 129000 | R3: 109601.16 | S3: 104148.67 | T3: =R3/Q3 -> 0.8496214 | U3: =R3/H3 -> 0.21240535 | V3: =R3/S3 -> 1.0523529 | W3: =H3-Q3 -> 387000 | AB3: 10110003 | AC3: 516000
A4: KWM | B4: 10110004 | C4: AUDIT & RISIKO-BAR | D4: B11000 | E4: 1-EMO | F4: EMOLUMEN | G4: BAR | H4: 532500 | I4: 200000 | J4: 196618.52 | K4: 239096.96 | L4: =J4/I4 -> 0.9830926 | M4: =J4/H4 -> 0.36923666 | N4: =J4/K4 -> 0.82233802 | O4: =H4-J4 -> 335881.48 | Q4: 120000 | R4: 97077.14 | S4: 122973.48 | T4: =R4/Q4 -> 0.80897617 | U4: =R4/H4 -> 0.18230449 | V4: =R4/S4 -> 0.78941525 | W4: =H4-Q4 -> 412500 | AB4: 10110004 | AC4: 532500
A5: KWM | B5: 10120001 | C5: SUMBER MANUSIA-BSM | D5: B11000 | E5: 1-EMO | F5: EMOLUMEN | G5: BSM | H5: 4380000 | I5: 1200000 | J5: 1101007.4 | K5: 63432.01 | L5: =J5/I5 -> 0.91750613 | M5: =J5/H5 -> 0.25137154 | N5: =J5/K5 -> 17.357283 | O5: =H5-J5 -> 3278992.6 | Q5: =473000+27700 -> 500700 | R5: 472220.38 | S5: 12190.04 | T5: =R5/Q5 -> 0.94312039 | U5: =R5/H5 -> 0.10781287 | V5: =R5/S5 -> 38.738214 | W5: =H5-Q5 -> 3879300 | AB5: 10120001 | AC5: 4380000
A6: KWM | B6: 10120002 | C6: TEKNOLOGI MAKLUMAT-BTM | D6: B11000 | E6: 1-EMO | F6: EMOLUMEN | G6: BTM | H6: 1669000 | I6: 800000 | J6: 757609.51 | K6: 687068.07 | L6: =J6/I6 -> 0.94701189 | M6: =J6/H6 -> 0.4539302 | N6: =J6/K6 -> 1.1026702 | O6: =H6-J6 -> 911390.49 | Q6: 417200 | R6: 374251.06 | S6: 347860.17 | T6: =R6/Q6 -> 0.89705431 | U6: =R6/H6 -> 0.2242367 | V6: =R6/S6 -> 1.0758664 | W6: =H6-Q6 -> 1251800 | AB6: 10120002 | AC6: 1669000
A7: KWM | B7: 10120003 | C7: KEWANGAN & AKAUN-BKA | D7: B11000 | E7: 1-EMO | F7: EMOLUMEN | G7: BKA | H7: 916000 | I7: 400000 | J7: 391715.48 | K7: 377576.54 | L7: =J7/I7 -> 0.9792887 | M7: =J7/H7 -> 0.42763699 | N7: =J7/K7 -> 1.0374466 | O7: =H7-J7 -> 524284.52 | Q7: 229000 | R7: 195188.86 | S7: 200571.14 | T7: =R7/Q7 -> 0.8523531 | U7: =R7/H7 -> 0.21308828 | V7: =R7/S7 -> 0.97316523 | W7: =H7-Q7 -> 687000 | AB7: 10120003 | AC7: 916000
A8: KWM | B8: 10120004 | C8: UNIT PENGURUSAN FASILITI-UPF | D8: B11000 | E8: 1-EMO | F8: EMOLUMEN | G8: UPF | H8: 568000 | I8: 300000 | J8: 255507.78 | K8: 239126.52 | L8: =J8/I8 -> 0.8516926 | M8: =J8/H8 -> 0.44983764 | N8: =J8/K8 -> 1.0685046 | O8: =H8-J8 -> 312492.22 | Q8: 142000 | R8: 127623.57 | S8: 121364.95 | T8: =R8/Q8 -> 0.89875754 | U8: =R8/H8 -> 0.22468938 | V8: =R8/S8 -> 1.0515686 | W8: =H8-Q8 -> 426000 | AB8: 10120004 | AC8: 568000
A9: KWM | B9: 10130001 | C9: PENGURUSAN LEVI-BPLV | D9: B11000 | E9: 1-EMO | F9: EMOLUMEN | G9: BPLV | H9: 1083000 | I9: 500000 | J9: 444028.29 | K9: 472348.69 | L9: =J9/I9 -> 0.88805658 | M9: =J9/H9 -> 0.40999842 | N9: =J9/K9 -> 0.94004345 | O9: =H9-J9 -> 638971.71 | Q9: 270700 | R9: 219896.8 | S9: 242310.37 | T9: =R9/Q9 -> 0.81232656 | U9: =R9/H9 -> 0.20304414 | V9: =R9/S9 -> 0.90750057 | W9: =H9-Q9 -> 812300 | AB9: 10130001 | AC9: 1083000
A10: KWM | B10: 10130003 | C10: PENGUATKUASAAN-BPGK | D10: B11000 | E10: 1-EMO | F10: EMOLUMEN | G10: BPGK | H10: 990000 | I10: 500000 | J10: 414247.23 | K10: 451456.83 | L10: =J10/I10 -> 0.82849446 | M10: =J10/H10 -> 0.41843155 | N10: =J10/K10 -> 0.91757883 | O10: =H10-J10 -> 575752.77 | Q10: 247500 | R10: 206279.54 | S10: 247845.19 | T10: =R10/Q10 -> 0.83345269 | U10: =R10/H10 -> 0.20836317 | V10: =R10/S10 -> 0.83229188 | W10: =H10-Q10 -> 742500 | AB10: 10130003 | AC10: 990000
A11: KWM | B11: 10130007 | C11: PEMATUHAN KUALITI BAHAN (BPKB) | D11: B11000 | E11: 1-EMO | F11: EMOLUMEN | G11: BPKB | H11: 713000 | I11: 350000 | J11: 315706.99 | K11: 304729.18 | L11: =J11/I11 -> 0.90201997 | M11: =J11/H11 -> 0.4427868 | N11: =J11/K11 -> 1.0360248 | O11: =H11-J11 -> 397293.01 | Q11: 178200 | R11: 158370.58 | S11: 161035.04 | T11: =R11/Q11 -> 0.88872379 | U11: =R11/H11 -> 0.22211863 | V11: =R11/S11 -> 0.98345416 | W11: =H11-Q11 -> 534800 | AB11: 10130007 | AC11: 713000
A12: KWM | B12: 10140007 | C12: PEMBANGUNAN TEKNOLOGI (BPT) | D12: B11000 | E12: 1-EMO | F12: EMOLUMEN | G12: BPT | H12: 609000 | I12: 300000 | J12: 272865.7 | K12: 239307.72 | L12: =J12/I12 -> 0.90955233 | M12: =J12/H12 -> 0.44805534 | N12: =J12/K12 -> 1.1402294 | O12: =H12-J12 -> 336134.3 | Q12: 152200 | R12: 137174.97 | S12: 130784.48 | T12: =R12/Q12 -> 0.90128101 | U12: =R12/H12 -> 0.22524626 | V12: =R12/S12 -> 1.0488628 | W12: =H12-Q12 -> 456800 | AB12: 10140007 | AC12: 609000
A13: KWM | B13: 10140008 | C13: PERSEKITARAN BISNES (BPS) | D13: B11000 | E13: 1-EMO | F13: EMOLUMEN | G13: BPS | H13: 337000 | I13: 170000 | J13: 151217.14 | K13: 138703.27 | L13: =J13/I13 -> 0.88951259 | M13: =J13/H13 -> 0.44871555 | N13: =J13/K13 -> 1.0902204 | O13: =H13-J13 -> 185782.86 | Q13: 84200 | R13: 75156.82 | S13: 70534.89 | T13: =R13/Q13 -> 0.89259881 | U13: =R13/H13 -> 0.22301727 | V13: =R13/S13 -> 1.0655269 | W13: =H13-Q13 -> 252800 | AB13: 10140008 | AC13: 337000
A14: KWM | B14: 10150008 | C14: PDFTRN KONTRAKTOR&PERSONEL BINAAN-BPKPB | D14: B11000 | E14: 1-EMO | F14: EMOLUMEN | G14: BPKPB | H14: 2070000 | I14: 1000000 | J14: 885325.22 | K14: 821492.47 | L14: =J14/I14 -> 0.88532522 | M14: =J14/H14 -> 0.42769334 | N14: =J14/K14 -> 1.0777034 | O14: =H14-J14 -> 1184674.8 | Q14: 517500 | R14: 450320.08 | S14: 404030.2 | T14: =R14/Q14 -> 0.87018373 | U14: =R14/H14 -> 0.21754593 | V14: =R14/S14 -> 1.1145703 | W14: =H14-Q14 -> 1552500 | AB14: 10150008 | AC14: 2070000
A15: KWM | B15: 10150009 | C15: LATIHAN & AKREDITASI (BLA) | D15: B11000 | E15: 1-EMO | F15: EMOLUMEN | G15: BLA | H15: =1352000+82000 -> 1434000 | I15: 700000 | J15: 654771.61 | K15: 512678.29 | L15: =J15/I15 -> 0.93538801 | M15: =J15/H15 -> 0.45660503 | N15: =J15/K15 -> 1.2771588 | O15: =H15-J15 -> 779228.39 | Q15: 358500 | R15: 326858.84 | S15: =243595.39+9832.45 -> 253427.84 | T15: =R15/Q15 -> 0.91174014 | U15: =R15/H15 -> 0.22793503 | V15: =R15/S15 -> 1.2897511 | W15: =H15-Q15 -> 1075500 | AB15: 10150009 | AC15: 1352000
A16: KWM | B16: 10150010 | C16: NA-PGRSNAKREDI(BPAK) | D16: B11000 | E16: 1-EMO | F16: EMOLUMEN | G16: BPAK | H16: 0 | I16: 0 | J16: 0 | K16: 9832.45 | L16: =J16/I16 -> #DIV/0! | M16: =J16/H16 -> #DIV/0! | N16: =J16/K16 -> 0 | O16: =H16-J16 -> 0 | AB16: 10150010 | AC16: 82000
A17: KWM | B17: 10160001 | C17: DASAR STRATEGI & TADBIR URUS-BSTU | D17: B11000 | E17: 1-EMO | F17: EMOLUMEN | G17: BSTU | H17: 2199000 | I17: 650000 | J17: 591531.86 | K17: 528545.94 | L17: =J17/I17 -> 0.91004902 | M17: =J17/H17 -> 0.26900039 | N17: =J17/K17 -> 1.1191683 | O17: =H17-J17 -> 1607468.1 | Q17: 320000 | R17: 299987.5 | S17: 254840.78 | T17: =R17/Q17 -> 0.93746094 | U17: =R17/H17 -> 0.13641996 | V17: =R17/S17 -> 1.1771566 | W17: =H17-Q17 -> 1879000 | AB17: 10160001 | AC17: 2199000
A18: KWM | B18: 10160003 | C18: KOMUNIKASI KORPORAT-BKK | D18: B11000 | E18: 1-EMO | F18: EMOLUMEN | G18: BKK | H18: 86000 | I18: 40000 | J18: 36918.61 | K18: 33391.42 | L18: =J18/I18 -> 0.92296525 | M18: =J18/H18 -> 0.42928616 | N18: =J18/K18 -> 1.1056316 | O18: =H18-J18 -> 49081.39 | Q18: 21500 | R18: 20385.68 | S18: 16822.82 | T18: =R18/Q18 -> 0.94817116 | U18: =R18/H18 -> 0.23704279 | V18: =R18/S18 -> 1.2117873 | W18: =H18-Q18 -> 64500 | AB18: 10160003 | AC18: 86000
A19: KWM | B19: 10170003 | C19: PEMBANGUNAN PERSONEL BINAAN (BPB) | D19: B11000 | E19: 1-EMO | F19: EMOLUMEN | G19: BPB | H19: 1237000 | I19: 550000 | J19: 497568.65 | K19: 493930.63 | L19: =J19/I19 -> 0.90467027 | M19: =J19/H19 -> 0.4022382 | N19: =J19/K19 -> 1.0073654 | O19: =H19-J19 -> 739431.35 | Q19: 309200 | R19: 249855.56 | S19: 233878.81 | T19: =R19/Q19 -> 0.80807102 | U19: =R19/H19 -> 0.20198509 | V19: =R19/S19 -> 1.0683121 | W19: =H19-Q19 -> 927800 | AB19: 10170003 | AC19: 1237000
A20: KWM | B20: 10170004 | C20: PEMBANGUNAN KONTRAKTOR (BPK) | D20: B11000 | E20: 1-EMO | F20: EMOLUMEN | G20: BPK | H20: 711000 | I20: 450000 | J20: 386757.83 | K20: 290396.79 | L20: =J20/I20 -> 0.85946184 | M20: =J20/H20 -> 0.54396319 | N20: =J20/K20 -> 1.3318254 | O20: =H20-J20 -> 324242.17 | Q20: 195000 | R20: 194240.32 | S20: 148339.02 | T20: =R20/Q20 -> 0.99610421 | U20: =R20/H20 -> 0.27319314 | V20: =R20/S20 -> 1.3094351 | W20: =H20-Q20 -> 516000 | AB20: 10170004 | AC20: 711000
A21: KWM | B21: 10200001 | C21: PL-PERLIS | D21: B11000 | E21: 1-EMO | F21: EMOLUMEN | G21: PL | H21: 357700 | I21: 200000 | J21: 174973.57 | K21: 168688.14 | L21: =J21/I21 -> 0.87486785 | M21: =J21/H21 -> 0.4891629 | N21: =J21/K21 -> 1.0372607 | O21: =H21-J21 -> 182726.43 | Q21: 89400 | R21: 86460.26 | S21: 83328.4 | T21: =R21/Q21 -> 0.967117 | U21: =R21/H21 -> 0.24171166 | V21: =R21/S21 -> 1.0375845 | W21: =H21-Q21 -> 268300 | AB21: 10200001 | AC21: 357700
A22: KWM | B22: 10200002 | C22: KD-KEDAH | D22: B11000 | E22: 1-EMO | F22: EMOLUMEN | G22: KD | H22: 910200 | I22: 500000 | J22: 438248.51 | K22: 417596.16 | L22: =J22/I22 -> 0.87649702 | M22: =J22/H22 -> 0.48148595 | N22: =J22/K22 -> 1.0494553 | O22: =H22-J22 -> 471951.49 | Q22: 227500 | R22: 223711.53 | S22: 214128.94 | T22: =R22/Q22 -> 0.98334738 | U22: =R22/H22 -> 0.24578283 | V22: =R22/S22 -> 1.0447515 | W22: =H22-Q22 -> 682700 | AB22: 10200002 | AC22: 910200
A23: KWM | B23: 10200003 | C23: PP-PULAU PINANG | D23: B11000 | E23: 1-EMO | F23: EMOLUMEN | G23: PP | H23: 1256000 | I23: 650000 | J23: 608741.6 | K23: 565723.08 | L23: =J23/I23 -> 0.93652554 | M23: =J23/H23 -> 0.48466688 | N23: =J23/K23 -> 1.0760417 | O23: =H23-J23 -> 647258.4 | Q23: 314000 | R23: 300471.72 | S23: 290381 | T23: =R23/Q23 -> 0.95691631 | U23: =R23/H23 -> 0.23922908 | V23: =R23/S23 -> 1.0347499 | W23: =H23-Q23 -> 942000 | AB23: 10200003 | AC23: 1256000
A24: KWM | B24: 10200004 | C24: PR-PERAK | D24: B11000 | E24: 1-EMO | F24: EMOLUMEN | G24: PR | H24: 998500 | I24: 590000 | J24: 499894.35 | K24: 402712.22 | L24: =J24/I24 -> 0.84727856 | M24: =J24/H24 -> 0.50064532 | N24: =J24/K24 -> 1.241319 | O24: =H24-J24 -> 498605.65 | Q24: 249600 | R24: 247130.64 | S24: 200764.95 | T24: =R24/Q24 -> 0.99010673 | U24: =R24/H24 -> 0.24750189 | V24: =R24/S24 -> 1.2309451 | W24: =H24-Q24 -> 748900 | AB24: 10200004 | AC24: 998500
A25: KWM | B25: 10200005 | C25: SL-SELANGOR | D25: B11000 | E25: 1-EMO | F25: EMOLUMEN | G25: SL | H25: 1313600 | I25: 700000 | J25: 603468.44 | K25: 575146.74 | L25: =J25/I25 -> 0.86209777 | M25: =J25/H25 -> 0.45940046 | N25: =J25/K25 -> 1.0492426 | O25: =H25-J25 -> 710131.56 | Q25: 328400 | R25: 298923.45 | S25: 290599.97 | T25: =R25/Q25 -> 0.91024193 | U25: =R25/H25 -> 0.22756048 | V25: =R25/S25 -> 1.0286424 | W25: =H25-Q25 -> 985200 | AB25: 10200005 | AC25: 1313600
A26: KWM | B26: 10200006 | C26: WP-WILAYAH PERSEKUTUAN (KL) | D26: B11000 | E26: 1-EMO | F26: EMOLUMEN | G26: WP | H26: 1284800 | I26: 650000 | J26: 595496.2 | K26: 594054.67 | L26: =J26/I26 -> 0.916148 | M26: =J26/H26 -> 0.46349331 | N26: =J26/K26 -> 1.0024266 | O26: =H26-J26 -> 689303.8 | Q26: 321200 | R26: 293087.68 | S26: 300873.92 | T26: =R26/Q26 -> 0.91247721 | U26: =R26/H26 -> 0.2281193 | V26: =R26/S26 -> 0.97412125 | W26: =H26-Q26 -> 963600 | AB26: 10200006 | AC26: 1284800
A27: KWM | B27: 10200007 | C27: NS-NEGERI SEMBILAN | D27: B11000 | E27: 1-EMO | F27: EMOLUMEN | G27: NS | H27: 839700 | I27: 400000 | J27: 387754.76 | K27: 396532.11 | L27: =J27/I27 -> 0.9693869 | M27: =J27/H27 -> 0.46177773 | N27: =J27/K27 -> 0.97786472 | O27: =H27-J27 -> 451945.24 | Q27: 209900 | R27: 202930.47 | S27: 210133.21 | T27: =R27/Q27 -> 0.96679595 | U27: =R27/H27 -> 0.2416702 | V27: =R27/S27 -> 0.96572298 | W27: =H27-Q27 -> 629800 | AB27: 10200007 | AC27: 839700
A28: KWM | B28: 10200008 | C28: ML-MELAKA | D28: B11000 | E28: 1-EMO | F28: EMOLUMEN | G28: ML | H28: 747100 | I28: 450000 | J28: 395188.45 | K28: 312279.4 | L28: =J28/I28 -> 0.87819656 | M28: =J28/H28 -> 0.52896326 | N28: =J28/K28 -> 1.2654964 | O28: =H28-J28 -> 351911.55 | Q28: 200000 | R28: 197760.21 | S28: 153754.67 | T28: =R28/Q28 -> 0.98880105 | U28: =R28/H28 -> 0.2647038 | V28: =R28/S28 -> 1.2862062 | W28: =H28-Q28 -> 547100 | AB28: 10200008 | AC28: 747100
... A52: KWM | B52: 10150008 | C52: PDFTRN KONTRAKTOR&PERSONEL BINAAN-BPKPB | D52: B21000 | E52: 2-EP | F52: PERBELANJAAN PERJALANAN DAN SARA HIDUP | G52: BPKPB | H52: 177000 | I52: 75000 | J52: 67716 | K52: 59470.72 | L52: =J52/I52 -> 0.90288 | M52: =J52/H52 -> 0.38257627 | N52: =J52/K52 -> 1.1386444 | O52: =H52-J52 -> 109284 | Q52: 29000 | R52: 25301.85 | S52: 21046.1 | T52: =R52/Q52 -> 0.87247759 | U52: =R52/H52 -> 0.14294831 | V52: =R52/S52 -> 1.2022109 | W52: =H52-Q52 -> 148000 | AB52: 10150008 | AC52: 177000
A53: KWM | B53: 10150009 | C53: LATIHAN & AKREDITASI (BLA) | D53: B21000 | E53: 2-EP | F53: PERBELANJAAN PERJALANAN DAN SARA HIDUP | G53: BLA | H53: 465000 | I53: 190000 | J53: 187026.76 | K53: 164772.97 | L53: =J53/I53 -> 0.98435137 | M53: =J53/H53 -> 0.40220809 | N53: =J53/K53 -> 1.1350573 | O53: =H53-J53 -> 277973.24 | Q53: 53000 | R53: 42899.81 | S53: =34704.2+1139.36 -> 35843.56 | T53: =R53/Q53 -> 0.80943038 | U53: =R53/H53 -> 0.092257656 | V53: =R53/S53 -> 1.1968624 | W53: =H53-Q53 -> 412000 | AB53: 10150009 | AC53: 465000
A54: KWM | B54: 10150010 | C54: NA-PGRSNAKREDI(BPAK) | D54: B21000 | E54: 2-EP | F54: PERBELANJAAN PERJALANAN DAN SARA HIDUP | G54: BPAK | H54: 0 | I54: 0 | J54: 0 | K54: 1139.36 | L54: =J54/I54 -> #DIV/0! | M54: =J54/H54 -> #DIV/0! | N54: =J54/K54 -> 0 | O54: =H54-J54 -> 0 | AB54: 10160001 | AC54: 60000
A55: KWM | B55: 10160001 | C55: DASAR STRATEGI & TADBIR URUS-BSTU | D55: B21000 | E55: 2-EP | F55: PERBELANJAAN PERJALANAN DAN SARA HIDUP | G55: BSTU | H55: 60000 | I55: 9400 | J55: 8715.94 | K55: 7819.06 | L55: =J55/I55 -> 0.92722766 | M55: =J55/H55 -> 0.14526567 | N55: =J55/K55 -> 1.1147043 | O55: =H55-J55 -> 51284.06 | Q55: 100 | R55: 55.8 | S55: 337.7 | T55: =R55/Q55 -> 0.558 | U55: =R55/H55 -> 0.00093 | V55: =R55/S55 -> 0.16523542 | W55: =H55-Q55 -> 59900 | AB55: 10160003 | AC55: 205000
A56: KWM | B56: 10160003 | C56: KOMUNIKASI KORPORAT-BKK | D56: B21000 | E56: 2-EP | F56: PERBELANJAAN PERJALANAN DAN SARA HIDUP | G56: BKK | H56: 205000 | I56: 72000 | J56: 70759 | K56: 48301.62 | L56: =J56/I56 -> 0.98276389 | M56: =J56/H56 -> 0.34516585 | N56: =J56/K56 -> 1.4649405 | O56: =H56-J56 -> 134241 | Q56: 21500 | R56: 17263.33 | S56: 7899.84 | T56: =R56/Q56 -> 0.80294558 | U56: =R56/H56 -> 0.084211366 | V56: =R56/S56 -> 2.1852759 | W56: =H56-Q56 -> 183500 | AB56: 10170003 | AC56: 233000
A57: KWM | B57: 10170003 | C57: PEMBANGUNAN PERSONEL BINAAN (BPB) | D57: B21000 | E57: 2-EP | F57: PERBELANJAAN PERJALANAN DAN SARA HIDUP | G57: BPB | H57: 233000 | I57: 46000 | J57: 45541.55 | K57: 126030.77 | L57: =J57/I57 -> 0.9900337 | M57: =J57/H57 -> 0.1954573 | N57: =J57/K57 -> 0.36135263 | O57: =H57-J57 -> 187458.45 | Q57: 25000 | R57: 20437.58 | S57: 3002.4 | T57: =R57/Q57 -> 0.8175032 | U57: =R57/H57 -> 0.087714936 | V57: =R57/S57 -> 6.807081 | W57: =H57-Q57 -> 208000 | AB57: 10170004 | AC57: 186000
A58: KWM | B58: 10170004 | C58: PEMBANGUNAN KONTRAKTOR (BPK) | D58: B21000 | E58: 2-EP | F58: PERBELANJAAN PERJALANAN DAN SARA HIDUP | G58: BPK | H58: 186000 | I58: 40000 | J58: 39688.22 | K58: 44256.24 | L58: =J58/I58 -> 0.9922055 | M58: =J58/H58 -> 0.21337753 | N58: =J58/K58 -> 0.89678247 | O58: =H58-J58 -> 146311.78 | Q58: 22000 | R58: 18387.39 | S58: 14988.95 | T58: =R58/Q58 -> 0.83579045 | U58: =R58/H58 -> 0.098856935 | V58: =R58/S58 -> 1.2267297 | W58: =H58-Q58 -> 164000 | AB58: 10200001 | AC58: 74500
A59: KWM | B59: 10200001 | C59: PL-PERLIS | D59: B21000 | E59: 2-EP | F59: PERBELANJAAN PERJALANAN DAN SARA HIDUP | G59: PL | H59: 74500 | I59: 15000 | J59: 14738.53 | K59: 26040.1 | L59: =J59/I59 -> 0.98256867 | M59: =J59/H59 -> 0.19783262 | N59: =J59/K59 -> 0.5659936 | O59: =H59-J59 -> 59761.47 | Q59: 5800 | R59: 4744.9 | S59: 9426.07 | T59: =R59/Q59 -> 0.81808621 | U59: =R59/H59 -> 0.063689933 | V59: =R59/S59 -> 0.50338052 | W59: =H59-Q59 -> 68700 | AB59: 10200002 | AC59: 112000
A60: KWM | B60: 10200002 | C60: KD-KEDAH | D60: B21000 | E60: 2-EP | F60: PERBELANJAAN PERJALANAN DAN SARA HIDUP | G60: KD | H60: 112000 | I60: 20000 | J60: 18934.17 | K60: 42260.24 | L60: =J60/I60 -> 0.9467085 | M60: =J60/H60 -> 0.16905509 | N60: =J60/K60 -> 0.44803745 | O60: =H60-J60 -> 93065.83 | Q60: 11000 | R60: 8944.79 | S60: 17168.02 | T60: =R60/Q60 -> 0.81316273 | U60: =R60/H60 -> 0.079864196 | V60: =R60/S60 -> 0.52101465 | W60: =H60-Q60 -> 101000 | AB60: 10200003 | AC60: 103000
A61: KWM | B61: 10200003 | C61: PP-PULAU PINANG | D61: B21000 | E61: 2-EP | F61: PERBELANJAAN PERJALANAN DAN SARA HIDUP | G61: PP | H61: 103000 | I61: 36000 | J61: 35236.59 | K61: 40168.29 | L61: =J61/I61 -> 0.97879417 | M61: =J61/H61 -> 0.34210282 | N61: =J61/K61 -> 0.87722405 | O61: =H61-J61 -> 67763.41 | Q61: =17600+400+1000 -> 19000 | R61: 16543.06 | S61: 15212.98 | T61: =R61/Q61 -> 0.87068737 | U61: =R61/H61 -> 0.16061223 | V61: =R61/S61 -> 1.0874306 | W61: =H61-Q61 -> 84000 | AB61: 10200004 | AC61: 93000
A62: KWM | B62: 10200004 | C62: PR-PERAK | D62: B21000 | E62: 2-EP | F62: PERBELANJAAN PERJALANAN DAN SARA HIDUP | G62: PR | H62: 93000 | I62: 20000 | J62: 18690.27 | K62: 38391.78 | L62: =J62/I62 -> 0.9345135 | M62: =J62/H62 -> 0.20097065 | N62: =J62/K62 -> 0.48682999 | O62: =H62-J62 -> 74309.73 | Q62: 3400 | R62: 2750.55 | S62: 13753.36 | T62: =R62/Q62 -> 0.80898529 | U62: =R62/H62 -> 0.029575806 | V62: =R62/S62 -> 0.19999113 | W62: =H62-Q62 -> 89600 | AB62: 10200005 | AC62: 130000
A63: KWM | B63: 10200005 | C63: SL-SELANGOR | D63: B21000 | E63: 2-EP | F63: PERBELANJAAN PERJALANAN DAN SARA HIDUP | G63: SL | H63: 130000 | I63: 54000 | J63: 53032.3 | K63: 51400.59 | L63: =J63/I63 -> 0.98207963 | M63: =J63/H63 -> 0.40794077 | N63: =J63/K63 -> 1.031745 | O63: =H63-J63 -> 76967.7 | Q63: 18500 | R63: 16294.99 | S63: 16827.47 | T63: =R63/Q63 -> 0.88081027 | U63: =R63/H63 -> 0.12534608 | V63: =R63/S63 -> 0.9683565 | W63: =H63-Q63 -> 111500 | AB63: 10200006 | AC63: 88000
...

Sheet B.MODAL
A1: Fund | B1: Funds Center | C1: Funds Center Description | D1: Funded Program | E1: Funded Program Desc | F1: KOD CI | G1: Commitment Item | H1: Commitment Item Description | I1: PTJ | J1: BAJET 2026 | K1: BAJET 06-2026 | L1: SEBENAR 06-2026 | M1: AUDITED 06-2025 | N1: PRESTASI 06-2026 | O1: PRESTASI 2026 | P1: PRESTASI 26 vs 25 | Q1: BAKI BAJET 2026 | S1: BAJET 03-2026 | T1: SEBENAR 03-2026 | U1: AUDITED 03-2025 | V1: PRESTASI 03-2026 | W1: PRESTASI 2026 | X1: PRESTASI 26 vs 25 | Y1: BAKI BAJET 2026
A2: KWM | B2: 10120004 | C2: UNIT PENGURUSAN FASILITI-UPF | F2: 1-KENDERAAN | G2: A34000 | H2: KENDERAAN | I2: UPF | J2: 1400000 | K2: 651000 | L2: 568500 | M2: 331944 | N2: =L2/K2 -> 0.87327189 | O2: =L2/J2 -> 0.40607143 | P2: =L2/M2 -> 1.7126383 | Q2: =J2-L2 -> 831500 | V2: =T2/S2 -> #DIV/0! | W2: =T2/J2 -> 0 | X2: =T2/U2 -> #DIV/0! | Y2: =J2-S2 -> 1400000
A3: KWM | B3: 10120004 | C3: UNIT PENGURUSAN FASILITI-UPF | F3: 2-K/PEJ | G3: A35000 | H3: KELENGKAPAN PEJABAT | I3: UPF | J3: 544900 | K3: 82600 | L3: 70357 | M3: 299013.2 | N3: =L3/K3 -> 0.85177966 | O3: =L3/J3 -> 0.1291191 | P3: =L3/M3 -> 0.2352973 | Q3: =J3-L3 -> 474543 | S3: 3900 | V3: =T3/S3 -> 0 | W3: =T3/J3 -> 0 | X3: =T3/U3 -> #DIV/0! | Y3: =J3-S3 -> 541000
A4: KWM | B4: 10200001 | C4: PL-PERLIS | F4: 2-K/PEJ | G4: A35000 | H4: KELENGKAPAN PEJABAT | I4: PL | J4: 25400 | K4: 25400 | L4: 25325 | N4: =L4/K4 -> 0.99704724 | O4: =L4/J4 -> 0.99704724 | P4: =L4/M4 -> #DIV/0! | Q4: =J4-L4 -> 75 | V4: =T4/S4 -> #DIV/0! | W4: =T4/J4 -> 0 | X4: =T4/U4 -> #DIV/0! | Y4: =J4-S4 -> 25400
A5: KWM | B5: 10200002 | C5: KD-KEDAH | F5: 2-K/PEJ | G5: A35000 | H5: KELENGKAPAN PEJABAT | I5: KD | J5: 89500 | K5: 20000 | L5: 16263.8 | N5: =L5/K5 -> 0.81319 | O5: =L5/J5 -> 0.18171844 | P5: =L5/M5 -> #DIV/0! | Q5: =J5-L5 -> 73236.2 | V5: =T5/S5 -> #DIV/0! | W5: =T5/J5 -> 0 | X5: =T5/U5 -> #DIV/0! | Y5: =J5-S5 -> 89500
A6: KWM | B6: 10200003 | C6: PP-PULAU PINANG | F6: 2-K/PEJ | G6: A35000 | H6: KELENGKAPAN PEJABAT | I6: PP | J6: 12000 | L6: 0 | N6: =L6/K6 -> #DIV/0! | O6: =L6/J6 -> 0 | P6: =L6/M6 -> #DIV/0! | Q6: =J6-L6 -> 12000 | V6: =T6/S6 -> #DIV/0! | W6: =T6/J6 -> 0 | X6: =T6/U6 -> #DIV/0! | Y6: =J6-S6 -> 12000
A7: KWM | B7: 10200004 | C7: PR-PERAK | F7: 2-K/PEJ | G7: A35000 | H7: KELENGKAPAN PEJABAT | I7: PR | J7: 35000 | L7: 0 | N7: =L7/K7 -> #DIV/0! | O7: =L7/J7 -> 0 | P7: =L7/M7 -> #DIV/0! | Q7: =J7-L7 -> 35000 | V7: =T7/S7 -> #DIV/0! | W7: =T7/J7 -> 0 | X7: =T7/U7 -> #DIV/0! | Y7: =J7-S7 -> 35000
A8: KWM | B8: 10200005 | C8: SL-SELANGOR | F8: 2-K/PEJ | G8: A35000 | H8: KELENGKAPAN PEJABAT | I8: SL | J8: 13000 | L8: 0 | N8: =L8/K8 -> #DIV/0! | O8: =L8/J8 -> 0 | P8: =L8/M8 -> #DIV/0! | Q8: =J8-L8 -> 13000 | V8: =T8/S8 -> #DIV/0! | W8: =T8/J8 -> 0 | X8: =T8/U8 -> #DIV/0! | Y8: =J8-S8 -> 13000
A9: KWM | B9: 10200006 | C9: WP-WILAYAH PERSEKUTUAN (KL) | F9: 2-K/PEJ | G9: A35000 | H9: KELENGKAPAN PEJABAT | I9: WP | J9: 49600 | K9: 35000 | L9: 30435 | N9: =L9/K9 -> 0.86957143 | O9: =L9/J9 -> 0.61360887 | P9: =L9/M9 -> #DIV/0! | Q9: =J9-L9 -> 19165 | S9: 35000 | T9: 28235 | V9: =T9/S9 -> 0.80671429 | W9: =T9/J9 -> 0.56925403 | X9: =T9/U9 -> #DIV/0! | Y9: =J9-S9 -> 14600
A10: KWM | B10: 10200007 | C10: NS-NEGERI SEMBILAN | F10: 2-K/PEJ | G10: A35000 | H10: KELENGKAPAN PEJABAT | I10: NS | J10: 20000 | L10: 0 | N10: =L10/K10 -> #DIV/0! | O10: =L10/J10 -> 0 | P10: =L10/M10 -> #DIV/0! | Q10: =J10-L10 -> 20000 | V10: =T10/S10 -> #DIV/0! | W10: =T10/J10 -> 0 | X10: =T10/U10 -> #DIV/0! | Y10: =J10-S10 -> 20000
A11: KWM | B11: 10200008 | C11: ML-MELAKA | F11: 2-K/PEJ | G11: A35000 | H11: KELENGKAPAN PEJABAT | I11: ML | J11: 20000 | K11: 20000 | L11: 17172 | N11: =L11/K11 -> 0.8586 | O11: =L11/J11 -> 0.8586 | P11: =L11/M11 -> #DIV/0! | Q11: =J11-L11 -> 2828 | V11: =T11/S11 -> #DIV/0! | W11: =T11/J11 -> 0 | X11: =T11/U11 -> #DIV/0! | Y11: =J11-S11 -> 20000
A12: KWM | B12: 10200009 | C12: JH-JOHOR | F12: 2-K/PEJ | G12: A35000 | H12: KELENGKAPAN PEJABAT | I12: JH | J12: 13000 | K12: 13000 | L12: 13000 | N12: =L12/K12 -> 1 | O12: =L12/J12 -> 1 | P12: =L12/M12 -> #DIV/0! | Q12: =J12-L12 -> 0 | V12: =T12/S12 -> #DIV/0! | W12: =T12/J12 -> 0 | X12: =T12/U12 -> #DIV/0! | Y12: =J12-S12 -> 13000
A13: KWM | B13: 10200011 | C13: TR-TERENGGANU | F13: 2-K/PEJ | G13: A35000 | H13: KELENGKAPAN PEJABAT | I13: TR | J13: 30000 | K13: 30000 | L13: 24246.9 | N13: =L13/K13 -> 0.80823 | O13: =L13/J13 -> 0.80823 | P13: =L13/M13 -> #DIV/0! | Q13: =J13-L13 -> 5753.1 | U13: 11210 | V13: =T13/S13 -> #DIV/0! | W13: =T13/J13 -> 0 | X13: =T13/U13 -> 0 | Y13: =J13-S13 -> 30000
A14: KWM | B14: 10200020 | C14: SR-SARAWAK | F14: 2-K/PEJ | G14: A35000 | H14: KELENGKAPAN PEJABAT | I14: SR | J14: 3000 | L14: 0 | N14: =L14/K14 -> #DIV/0! | O14: =L14/J14 -> 0 | P14: =L14/M14 -> #DIV/0! | Q14: =J14-L14 -> 3000 | V14: =T14/S14 -> #DIV/0! | W14: =T14/J14 -> 0 | X14: =T14/U14 -> #DIV/0! | Y14: =J14-S14 -> 3000
A15: KWM | B15: 10200021 | C15: MR-MIRI | F15: 2-K/PEJ | G15: A35000 | H15: KELENGKAPAN PEJABAT | I15: MR | J15: 4000 | L15: 0 | N15: =L15/K15 -> #DIV/0! | O15: =L15/J15 -> 0 | P15: =L15/M15 -> #DIV/0! | Q15: =J15-L15 -> 4000 | V15: =T15/S15 -> #DIV/0! | W15: =T15/J15 -> 0 | X15: =T15/U15 -> #DIV/0! | Y15: =J15-S15 -> 4000
A16: KWM | B16: 10200023 | C16: SI-SIBU | F16: 2-K/PEJ | G16: A35000 | H16: KELENGKAPAN PEJABAT | I16: SI | J16: 9100 | K16: 4000 | L16: 3950 | N16: =L16/K16 -> 0.9875 | O16: =L16/J16 -> 0.43406593 | P16: =L16/M16 -> #DIV/0! | Q16: =J16-L16 -> 5150 | V16: =T16/S16 -> #DIV/0! | W16: =T16/J16 -> 0 | X16: =T16/U16 -> #DIV/0! | Y16: =J16-S16 -> 9100
A17: KWM | B17: 10200030 | C17: SB-SABAH | F17: 2-K/PEJ | G17: A35000 | H17: KELENGKAPAN PEJABAT | I17: SB | J17: 24000 | L17: 0 | N17: =L17/K17 -> #DIV/0! | O17: =L17/J17 -> 0 | P17: =L17/M17 -> #DIV/0! | Q17: =J17-L17 -> 24000 | V17: =T17/S17 -> #DIV/0! | W17: =T17/J17 -> 0 | X17: =T17/U17 -> #DIV/0! | Y17: =J17-S17 -> 24000
A18: KWM | B18: 10200031 | C18: TW-TAWAU | F18: 2-K/PEJ | G18: A35000 | H18: KELENGKAPAN PEJABAT | I18: TW | J18: 35000 | L18: 0 | N18: =L18/K18 -> #DIV/0! | O18: =L18/J18 -> 0 | P18: =L18/M18 -> #DIV/0! | Q18: =J18-L18 -> 35000 | V18: =T18/S18 -> #DIV/0! | W18: =T18/J18 -> 0 | X18: =T18/U18 -> #DIV/0! | Y18: =J18-S18 -> 35000
A19: KWM | B19: 10200032 | C19: SD-SANDAKAN | F19: 2-K/PEJ | G19: A35000 | H19: KELENGKAPAN PEJABAT | I19: SD | J19: 6000 | L19: 0 | N19: =L19/K19 -> #DIV/0! | O19: =L19/J19 -> 0 | P19: =L19/M19 -> #DIV/0! | Q19: =J19-L19 -> 6000 | V19: =T19/S19 -> #DIV/0! | W19: =T19/J19 -> 0 | X19: =T19/U19 -> #DIV/0! | Y19: =J19-S19 -> 6000
A20: KWM | B20: 10120002 | C20: TEKNOLOGI MAKLUMAT-BTM | F20: 3-KOMPUTER | G20: A38000 | H20: KOMPUTER | I20: BTM | J20: 2750000 | K20: 55000 | L20: =43810.2+4536 -> 48346.2 | N20: =L20/K20 -> 0.87902182 | O20: =L20/J20 -> 0.017580436 | P20: =L20/M20 -> #DIV/0! | Q20: =J20-L20 -> 2701653.8 | V20: =T20/S20 -> #DIV/0! | W20: =T20/J20 -> 0 | X20: =T20/U20 -> #DIV/0! | Y20: =J20-S20 -> 2750000
A21: KWM | B21: 10120004 | C21: UNIT PENGURUSAN FASILITI-UPF | F21: 4-PERABOT | G21: A39200 | H21: PERABOT & LENGKAPAN | I21: UPF | J21: 136500 | K21: 1000 | N21: =L21/K21 -> 0 | O21: =L21/J21 -> 0 | P21: =L21/M21 -> #DIV/0! | Q21: =J21-L21 -> 136500 | V21: =T21/S21 -> #DIV/0! | W21: =T21/J21 -> 0 | X21: =T21/U21 -> #DIV/0! | Y21: =J21-S21 -> 136500
A22: KWM | B22: 10200003 | C22: PP-PULAU PINANG | F22: 4-PERABOT | G22: A39200 | H22: PERABOT & LENGKAPAN | I22: PP | J22: 20000 | N22: =L22/K22 -> #DIV/0! | O22: =L22/J22 -> 0 | P22: =L22/M22 -> #DIV/0! | Q22: =J22-L22 -> 20000 | V22: =T22/S22 -> #DIV/0! | W22: =T22/J22 -> 0 | X22: =T22/U22 -> #DIV/0! | Y22: =J22-S22 -> 20000
A23: KWM | B23: 10200004 | C23: PR-PERAK | F23: 4-PERABOT | G23: A39200 | H23: PERABOT & LENGKAPAN | I23: PR | J23: 8000 | K23: 8000 | L23: 7998 | M23: 8700 | N23: =L23/K23 -> 0.99975 | O23: =L23/J23 -> 0.99975 | P23: =L23/M23 -> 0.91931034 | Q23: =J23-L23 -> 2 | U23: 8700 | V23: =T23/S23 -> #DIV/0! | W23: =T23/J23 -> 0 | X23: =T23/U23 -> 0 | Y23: =J23-S23 -> 8000
